2020-05-15 02:39:15 [fake_useragent] WARNING: Error occurred during loading data. Trying to use cache server https://fake-useragent.herokuapp.com/browsers/0.1.11
Traceback (most recent call last):
  File "C:\Users\Administrator\AppData\Local\Programs\Python\Python36-32\lib\urllib\request.py", line 1318, in do_open
    encode_chunked=req.has_header('Transfer-encoding'))
  File "C:\Users\Administrator\AppData\Local\Programs\Python\Python36-32\lib\http\client.py", line 1239, in request
    self._send_request(method, url, body, headers, encode_chunked)
  File "C:\Users\Administrator\AppData\Local\Programs\Python\Python36-32\lib\http\client.py", line 1285, in _send_request
    self.endheaders(body, encode_chunked=encode_chunked)
  File "C:\Users\Administrator\AppData\Local\Programs\Python\Python36-32\lib\http\client.py", line 1234, in endheaders
    self._send_output(message_body, encode_chunked=encode_chunked)
  File "C:\Users\Administrator\AppData\Local\Programs\Python\Python36-32\lib\http\client.py", line 1026, in _send_output
    self.send(msg)
  File "C:\Users\Administrator\AppData\Local\Programs\Python\Python36-32\lib\http\client.py", line 964, in send
    self.connect()
  File "C:\Users\Administrator\AppData\Local\Programs\Python\Python36-32\lib\http\client.py", line 1392, in connect
    super().connect()
  File "C:\Users\Administrator\AppData\Local\Programs\Python\Python36-32\lib\http\client.py", line 936, in connect
    (self.host,self.port), self.timeout, self.source_address)
  File "C:\Users\Administrator\AppData\Local\Programs\Python\Python36-32\lib\socket.py", line 724, in create_connection
    raise err
  File "C:\Users\Administrator\AppData\Local\Programs\Python\Python36-32\lib\socket.py", line 713, in create_connection
    sock.connect(sa)
socket.timeout: timed out

During handling of the above exception, another exception occurred:

Traceback (most recent call last):
  File "C:\Users\Administrator\AppData\Local\Temp\py_tornado\lib\site-packages\fake_useragent\utils.py", line 67, in get
    context=context,
  File "C:\Users\Administrator\AppData\Local\Programs\Python\Python36-32\lib\urllib\request.py", line 223, in urlopen
    return opener.open(url, data, timeout)
  File "C:\Users\Administrator\AppData\Local\Programs\Python\Python36-32\lib\urllib\request.py", line 526, in open
    response = self._open(req, data)
  File "C:\Users\Administrator\AppData\Local\Programs\Python\Python36-32\lib\urllib\request.py", line 544, in _open
    '_open', req)
  File "C:\Users\Administrator\AppData\Local\Programs\Python\Python36-32\lib\urllib\request.py", line 504, in _call_chain
    result = func(*args)
  File "C:\Users\Administrator\AppData\Local\Programs\Python\Python36-32\lib\urllib\request.py", line 1361, in https_open
    context=self._context, check_hostname=self._check_hostname)
  File "C:\Users\Administrator\AppData\Local\Programs\Python\Python36-32\lib\urllib\request.py", line 1320, in do_open
    raise URLError(err)
urllib.error.URLError: <urlopen error timed out>

During handling of the above exception, another exception occurred:

Traceback (most recent call last):
  File "C:\Users\Administrator\AppData\Local\Temp\py_tornado\lib\site-packages\fake_useragent\utils.py", line 154, in load
    for item in get_browsers(verify_ssl=verify_ssl):
  File "C:\Users\Administrator\AppData\Local\Temp\py_tornado\lib\site-packages\fake_useragent\utils.py", line 97, in get_browsers
    html = get(settings.BROWSERS_STATS_PAGE, verify_ssl=verify_ssl)
  File "C:\Users\Administrator\AppData\Local\Temp\py_tornado\lib\site-packages\fake_useragent\utils.py", line 84, in get
    raise FakeUserAgentError('Maximum amount of retries reached')
fake_useragent.errors.FakeUserAgentError: Maximum amount of retries reached
2020-05-15 02:39:19 [scrapy.core.scraper] ERROR: Spider error processing <GET https://movie.douban.com/top250> (referer: None)
Traceback (most recent call last):
  File "C:\Users\Administrator\AppData\Local\Temp\py_tornado\lib\site-packages\scrapy\utils\defer.py", line 117, in iter_errback
    yield next(it)
  File "C:\Users\Administrator\AppData\Local\Temp\py_tornado\lib\site-packages\scrapy\utils\python.py", line 345, in __next__
    return next(self.data)
  File "C:\Users\Administrator\AppData\Local\Temp\py_tornado\lib\site-packages\scrapy\utils\python.py", line 345, in __next__
    return next(self.data)
  File "C:\Users\Administrator\AppData\Local\Temp\py_tornado\lib\site-packages\scrapy\core\spidermw.py", line 64, in _evaluate_iterable
    for r in iterable:
  File "C:\Users\Administrator\AppData\Local\Temp\py_tornado\lib\site-packages\scrapy\spidermiddlewares\offsite.py", line 29, in process_spider_output
    for x in result:
  File "C:\Users\Administrator\AppData\Local\Temp\py_tornado\lib\site-packages\scrapy\core\spidermw.py", line 64, in _evaluate_iterable
    for r in iterable:
  File "C:\Users\Administrator\AppData\Local\Temp\py_tornado\lib\site-packages\scrapy\spidermiddlewares\referer.py", line 338, in <genexpr>
    return (_set_referer(r) for r in result or ())
  File "C:\Users\Administrator\AppData\Local\Temp\py_tornado\lib\site-packages\scrapy\core\spidermw.py", line 64, in _evaluate_iterable
    for r in iterable:
  File "C:\Users\Administrator\AppData\Local\Temp\py_tornado\lib\site-packages\scrapy\spidermiddlewares\urllength.py", line 37, in <genexpr>
    return (r for r in result or () if _filter(r))
  File "C:\Users\Administrator\AppData\Local\Temp\py_tornado\lib\site-packages\scrapy\core\spidermw.py", line 64, in _evaluate_iterable
    for r in iterable:
  File "C:\Users\Administrator\AppData\Local\Temp\py_tornado\lib\site-packages\scrapy\spidermiddlewares\depth.py", line 58, in <genexpr>
    return (r for r in result or () if _filter(r))
  File "C:\Users\Administrator\AppData\Local\Temp\py_tornado\lib\site-packages\scrapy\core\spidermw.py", line 64, in _evaluate_iterable
    for r in iterable:
  File "C:\Users\Administrator\Desktop\tt\MyScrapy\MyScrapy\spiders\douban.py", line 13, in parse
    print(response.he)
AttributeError: 'HtmlResponse' object has no attribute 'he'
2020-05-15 02:41:08 [scrapy.core.scraper] ERROR: Spider error processing <GET https://movie.douban.com/top250> (referer: None)
Traceback (most recent call last):
  File "C:\Users\Administrator\AppData\Local\Temp\py_tornado\lib\site-packages\scrapy\utils\defer.py", line 117, in iter_errback
    yield next(it)
  File "C:\Users\Administrator\AppData\Local\Temp\py_tornado\lib\site-packages\scrapy\utils\python.py", line 345, in __next__
    return next(self.data)
  File "C:\Users\Administrator\AppData\Local\Temp\py_tornado\lib\site-packages\scrapy\utils\python.py", line 345, in __next__
    return next(self.data)
  File "C:\Users\Administrator\AppData\Local\Temp\py_tornado\lib\site-packages\scrapy\core\spidermw.py", line 64, in _evaluate_iterable
    for r in iterable:
  File "C:\Users\Administrator\AppData\Local\Temp\py_tornado\lib\site-packages\scrapy\spidermiddlewares\offsite.py", line 29, in process_spider_output
    for x in result:
  File "C:\Users\Administrator\AppData\Local\Temp\py_tornado\lib\site-packages\scrapy\core\spidermw.py", line 64, in _evaluate_iterable
    for r in iterable:
  File "C:\Users\Administrator\AppData\Local\Temp\py_tornado\lib\site-packages\scrapy\spidermiddlewares\referer.py", line 338, in <genexpr>
    return (_set_referer(r) for r in result or ())
  File "C:\Users\Administrator\AppData\Local\Temp\py_tornado\lib\site-packages\scrapy\core\spidermw.py", line 64, in _evaluate_iterable
    for r in iterable:
  File "C:\Users\Administrator\AppData\Local\Temp\py_tornado\lib\site-packages\scrapy\spidermiddlewares\urllength.py", line 37, in <genexpr>
    return (r for r in result or () if _filter(r))
  File "C:\Users\Administrator\AppData\Local\Temp\py_tornado\lib\site-packages\scrapy\core\spidermw.py", line 64, in _evaluate_iterable
    for r in iterable:
  File "C:\Users\Administrator\AppData\Local\Temp\py_tornado\lib\site-packages\scrapy\spidermiddlewares\depth.py", line 58, in <genexpr>
    return (r for r in result or () if _filter(r))
  File "C:\Users\Administrator\AppData\Local\Temp\py_tornado\lib\site-packages\scrapy\core\spidermw.py", line 64, in _evaluate_iterable
    for r in iterable:
  File "C:\Users\Administrator\Desktop\tt\MyScrapy\MyScrapy\spiders\douban.py", line 13, in parse
    print(response.he)
AttributeError: 'HtmlResponse' object has no attribute 'he'
